[2024-07-01 21:26:08,298][    INFO] {'batch_size': 1,
 'control': 'ethn',
 'crop_size': 256,
 'data_desc': 'UKBB Test Data - Ethnicity Controlled -  108 Patients',
 'data_root': '/vol/aimspace/projects/ukbb/data/cardiac/cardiac_segmentations/subjects',
 'dataset': 'ukbb',
 'exp': '4',
 'method': 'supervised',
 'mode': 'test',
 'model': 'unimatch unet',
 'model_desc': 'Unimatch Unet 18 Pretrained on UKBB',
 'model_path': 'exp/ukbb/unimatch/unet/18/seed42/multi_task/best.pth',
 'multi_task': True,
 'nclass': 4,
 'num_workers': 1,
 'pred_mask_path': 'outputs/results/imgs/ukbb/supervised/4/18/seed42',
 'results_path': 'outputs/results/csv/ukbb/exp4/seed42/multi_task/ethn.csv',
 'seed': '42',
 'split': 18,
 'test_set': 108,
 'test_split_path': 'splits/ukbb/test/ethn.csv',
 'train_set': 182,
 'visualize': False}

Traceback (most recent call last):
  File "/vol/aimspace/users/khattab/UniMatch/more-scenarios/medical/inference.py", line 77, in <module>
    main()
  File "/vol/aimspace/users/khattab/UniMatch/more-scenarios/medical/inference.py", line 46, in main
    checkpoint = torch.load(cfg['model_path'])
                 ^^^^^^^^^^^^^^^^^^^^^^^^^^^^^
  File "/u/home/khattab/.conda/envs/unimatch/lib/python3.11/site-packages/torch/serialization.py", line 997, in load
    with _open_file_like(f, 'rb') as opened_file:
         ^^^^^^^^^^^^^^^^^^^^^^^^
  File "/u/home/khattab/.conda/envs/unimatch/lib/python3.11/site-packages/torch/serialization.py", line 444, in _open_file_like
    return _open_file(name_or_buffer, mode)
           ^^^^^^^^^^^^^^^^^^^^^^^^^^^^^^^^
  File "/u/home/khattab/.conda/envs/unimatch/lib/python3.11/site-packages/torch/serialization.py", line 425, in __init__
    super().__init__(open(name, mode))
                     ^^^^^^^^^^^^^^^^
FileNotFoundError: [Errno 2] No such file or directory: 'exp/ukbb/unimatch/unet/18/seed42/multi_task/best.pth'
